<?xml version="1.0" encoding="UTF-8"?>
<robot name="fetch_moveit_try">
  <joint name="bellows_joint" type="prismatic">
    <origin xyz="0. 0. 0." rpy="3.1415927 0. 3.1415927"/>
    <parent link="torso_lift_link"/>
    <child link="bellows_link"/>
    <axis xyz="1. 0. 0."/>
    <limit lower="0." upper="0.4" effort="5." velocity="0.1"/>
  </joint>
  <joint name="bellows_joint2" type="fixed">
    <origin xyz="0. 0. 0." rpy="0. 1.5707963 0. "/>
    <parent link="torso_lift_link"/>
    <child link="bellows_link2"/>
  </joint>
  <joint name="elbow_flex_joint" type="revolute">
    <origin xyz="0.133 0. 0. " rpy="0. 0. 1.5707964"/>
    <parent link="upperarm_roll_link"/>
    <child link="elbow_flex_link"/>
    <axis xyz="1. 0. 0."/>
    <limit lower="-2.2509999" upper="2.2509999" effort="66.1800003" velocity="1.521"/>
  </joint>
  <joint name="estop_joint" type="fixed">
    <origin xyz="-0.12465 0.23892 0.31127" rpy="1.5707964 -0.0000036 1.5707964"/>
    <parent link="fetch"/>
    <child link="estop_link"/>
  </joint>
  <joint name="forearm_roll_joint" type="continuous">
    <origin xyz="0. -0.197 0. " rpy="0. 0. -1.5707964"/>
    <parent link="elbow_flex_link"/>
    <child link="forearm_roll_link"/>
    <axis xyz="1. 0. 0."/>
  </joint>
  <joint name="gripper_axis" type="fixed">
    <origin xyz="0.16645 0. 0. " rpy="0. 0. 1.5707964"/>
    <parent link="wrist_roll_link"/>
    <child link="gripper_link"/>
  </joint>
  <joint name="head_camera_depth_joint" type="fixed">
    <origin xyz="0. 0.045 0. " rpy="0. 0. 0."/>
    <parent link="head_camera_link"/>
    <child link="head_camera_depth_frame"/>
  </joint>
  <joint name="head_camera_depth_optical_joint" type="fixed">
    <origin xyz="0. 0. 0." rpy="-1.5707964 0. -1.5707964"/>
    <parent link="head_camera_depth_frame"/>
    <child link="head_camera_depth_optical_frame"/>
  </joint>
  <joint name="head_camera_joint" type="fixed">
    <origin xyz="0. -0.055 0.0225" rpy="0. 0. -1.5707964"/>
    <parent link="head_tilt_link"/>
    <child link="head_camera_link"/>
  </joint>
  <joint name="head_camera_rgb_joint" type="fixed">
    <origin xyz="0. 0.02 0. " rpy="0. 0. 0."/>
    <parent link="head_camera_link"/>
    <child link="head_camera_rgb_frame"/>
  </joint>
  <joint name="head_camera_rgb_optical_joint" type="fixed">
    <origin xyz="0. 0. 0." rpy="-1.5707964 0. -1.5707964"/>
    <parent link="head_camera_rgb_frame"/>
    <child link="head_camera_rgb_optical_frame"/>
  </joint>
  <joint name="head_pan_joint" type="revolute">
    <origin xyz="0.6030014 0. -0.053125 " rpy="0. 0. 0."/>
    <parent link="torso_lift_link"/>
    <child link="head_pan_link"/>
    <axis xyz="1. 0. 0."/>
    <limit lower="-1.5699999" upper="1.5699999" effort="0.32" velocity="1.57"/>
  </joint>
  <joint name="head_tilt_joint" type="revolute">
    <origin xyz="0.057999 0. -0.14253 " rpy="1.5707964 0. 1.5707964"/>
    <parent link="head_pan_link"/>
    <child link="head_tilt_link"/>
    <axis xyz="1. 0. 0."/>
    <limit lower="-0.7599999" upper="1.45" effort="0.68" velocity="1.57"/>
  </joint>
  <joint name="joint_head_camera_link-Camera_OmniVision_OV9782_Color" type="fixed">
    <origin xyz="0.0012938 0. 0.0000523" rpy="1.5707964 0. -1.5707964"/>
    <parent link="head_camera_link"/>
    <child link="Camera_OmniVision_OV9782_Color"/>
  </joint>
  <joint name="joint_head_camera_link-Camera_OmniVision_OV9782_Left" type="fixed">
    <origin xyz="0.0012938 0.0475 0.0000523" rpy="1.5707964 0. -1.5707964"/>
    <parent link="head_camera_link"/>
    <child link="Camera_OmniVision_OV9782_Left"/>
  </joint>
  <joint name="joint_head_camera_link-Camera_OmniVision_OV9782_Right" type="fixed">
    <origin xyz="0.0012938 -0.0475 0.0000523" rpy="1.5707964 0. -1.5707964"/>
    <parent link="head_camera_link"/>
    <child link="Camera_OmniVision_OV9782_Right"/>
  </joint>
  <joint name="joint_head_camera_link-Camera_Pseudo_Depth" type="fixed">
    <origin xyz="0.0012938 0. 0.0000523" rpy="1.5707964 0. -1.5707964"/>
    <parent link="head_camera_link"/>
    <child link="Camera_Pseudo_Depth"/>
  </joint>
  <joint name="joint_head_camera_link-Imu_Sensor" type="fixed">
    <origin xyz="-0.0147062 0.01728 0.0074523" rpy="0. 0. 3.1415927"/>
    <parent link="head_camera_link"/>
    <child link="Imu_Sensor"/>
  </joint>
  <joint name="l_gripper_finger_joint" type="prismatic">
    <origin xyz="-0.015425 0. 0. " rpy="0. 0. 3.1415927"/>
    <parent link="gripper_link"/>
    <child link="l_gripper_finger_link"/>
    <axis xyz="1. 0. 0."/>
    <limit lower="0." upper="0.05" effort="60." velocity="0.05"/>
  </joint>
  <joint name="l_wheel_joint" type="continuous">
    <origin xyz="0.0012914 0.18738 0.055325 " rpy="0. 0. 1.5707964"/>
    <parent link="fetch"/>
    <child link="l_wheel_link"/>
    <axis xyz="1. 0. 0."/>
  </joint>
  <joint name="laser_joint" type="fixed">
    <origin xyz="0.235 0. 0.2878" rpy="3.1415927 -1.5707963 0. "/>
    <parent link="fetch"/>
    <child link="laser_link"/>
  </joint>
  <joint name="r_gripper_finger_joint" type="prismatic">
    <origin xyz="0.015425 0. 0. " rpy="0. 0. 0."/>
    <parent link="gripper_link"/>
    <child link="r_gripper_finger_link"/>
    <axis xyz="1. 0. 0."/>
    <limit lower="0." upper="0.05" effort="60." velocity="0.05"/>
  </joint>
  <joint name="r_wheel_joint" type="continuous">
    <origin xyz="0.0012914 -0.18738 0.055325 " rpy="0. 0. 1.5707964"/>
    <parent link="fetch"/>
    <child link="r_wheel_link"/>
    <axis xyz="1. 0. 0."/>
  </joint>
  <joint name="shoulder_lift_joint" type="revolute">
    <origin xyz="0.06 0. -0.117" rpy="1.5707964 0. 1.5707964"/>
    <parent link="shoulder_pan_link"/>
    <child link="shoulder_lift_link"/>
    <axis xyz="1. 0. 0."/>
    <limit lower="-1.2209998" upper="1.518" effort="131.7599945" velocity="1.4539999"/>
  </joint>
  <joint name="shoulder_pan_joint" type="revolute">
    <origin xyz="0.34858 0. -0.119525" rpy="0. 0. 0."/>
    <parent link="torso_lift_link"/>
    <child link="shoulder_pan_link"/>
    <axis xyz="1. 0. 0."/>
    <limit lower="-1.6055998" upper="1.6055998" effort="33.8199997" velocity="1.256"/>
  </joint>
  <joint name="torso_fixed_joint" type="fixed">
    <origin xyz="-0.086875 0. 0.377425" rpy="0. 0. 1.5707964"/>
    <parent link="fetch"/>
    <child link="torso_fixed_link"/>
  </joint>
  <joint name="torso_lift_joint" type="prismatic">
    <origin xyz="-0.086875 0. 0.37743 " rpy="0. -1.5707963 0. "/>
    <parent link="fetch"/>
    <child link="torso_lift_link"/>
    <axis xyz="1. 0. 0."/>
    <limit lower="0." upper="0.38615" effort="450." velocity="0.1"/>
  </joint>
  <joint name="upperarm_roll_joint" type="continuous">
    <origin xyz="0. -0.219 0. " rpy="0. 0. -1.5707964"/>
    <parent link="shoulder_lift_link"/>
    <child link="upperarm_roll_link"/>
    <axis xyz="1. 0. 0."/>
  </joint>
  <joint name="wrist_flex_joint" type="revolute">
    <origin xyz="0.1245 0. 0. " rpy="0. 0. 1.5707964"/>
    <parent link="forearm_roll_link"/>
    <child link="wrist_flex_link"/>
    <axis xyz="1. 0. 0."/>
    <limit lower="-2.1599999" upper="2.1599999" effort="25.7000008" velocity="2.2679999"/>
  </joint>
  <joint name="wrist_roll_joint" type="continuous">
    <origin xyz="0. -0.1385 0. " rpy="0. 0. -1.5707964"/>
    <parent link="wrist_flex_link"/>
    <child link="wrist_roll_link"/>
    <axis xyz="1. 0. 0."/>
  </joint>
  <link name="Camera_OmniVision_OV9782_Color"/>
  <link name="Camera_OmniVision_OV9782_Color_OmniverseKitViewportCameraMesh"/>
  <link name="Camera_OmniVision_OV9782_Left"/>
  <link name="Camera_OmniVision_OV9782_Left_OmniverseKitViewportCameraMesh"/>
  <link name="Camera_OmniVision_OV9782_Right"/>
  <link name="Camera_OmniVision_OV9782_Right_OmniverseKitViewportCameraMesh"/>
  <link name="Camera_Pseudo_Depth"/>
  <link name="Camera_Pseudo_Depth_OmniverseKitViewportCameraMesh"/>
  <link name="Imu_Sensor"/>
  <link name="bellows_link">
    <inertial>
      <origin xyz="0. 0. 0." rpy="0. 0. 0."/>
      <mass value="0.169374"/>
      <inertia ixx="0." ixy="0." ixz="0." iyy="0." iyz="0." izz="0."/>
    </inertial>
    <visual>
      <origin xyz="0. 0. 0." rpy="0. -1.5707963 0. "/>
      <geometry>
        <mesh filename="meshes/bellows_link_visuals.obj" scale="1. 1. 1."/>
      </geometry>
    </visual>
    <visual>
      <origin xyz="0. 0. 0." rpy="0. -1.5707963 0. "/>
      <geometry>
        <mesh filename="meshes/bellows_link_collisions.obj" scale="1. 1. 1."/>
      </geometry>
    </visual>
    <collision>
      <origin xyz="0. 0. 0." rpy="0. -1.5707963 0. "/>
      <geometry>
        <mesh filename="meshes/bellows_link_collisions.obj" scale="1. 1. 1."/>
      </geometry>
    </collision>
  </link>
  <link name="bellows_link2">
    <inertial>
      <origin xyz="0. 0. 0." rpy="0. 0. 0."/>
      <mass value="0.169374"/>
      <inertia ixx="0." ixy="0." ixz="0." iyy="0." iyz="0." izz="0."/>
    </inertial>
    <visual>
      <origin xyz="0. 0. 0." rpy="0. 0. 0."/>
      <geometry>
        <mesh filename="meshes/bellows_link2_visuals.obj" scale="1. 1. 1."/>
      </geometry>
    </visual>
    <visual>
      <origin xyz="0. 0. 0." rpy="0. 0. 0."/>
      <geometry>
        <mesh filename="meshes/bellows_link2_collisions.obj" scale="1. 1. 1."/>
      </geometry>
    </visual>
    <collision>
      <origin xyz="0. 0. 0." rpy="0. 0. 0."/>
      <geometry>
        <mesh filename="meshes/bellows_link2_collisions.obj" scale="1. 1. 1."/>
      </geometry>
    </collision>
  </link>
  <link name="elbow_flex_link">
    <inertial>
      <origin xyz="0. 0. 0." rpy="0. 0. 0."/>
      <mass value="2.1299"/>
      <inertia ixx="0." ixy="0." ixz="0." iyy="0." iyz="0." izz="0."/>
    </inertial>
    <visual>
      <origin xyz="0. 0. 0." rpy="0. 0. -1.5707964"/>
      <geometry>
        <mesh filename="meshes/elbow_flex_link_visuals.obj" scale="1. 1. 1."/>
      </geometry>
    </visual>
    <visual>
      <origin xyz="0. 0. 0." rpy="0. 0. -1.5707964"/>
      <geometry>
        <mesh filename="meshes/elbow_flex_link_collisions.obj" scale="1. 1. 1."/>
      </geometry>
    </visual>
    <collision>
      <origin xyz="0. 0. 0." rpy="0. 0. -1.5707964"/>
      <geometry>
        <mesh filename="meshes/elbow_flex_link_collisions.obj" scale="1. 1. 1."/>
      </geometry>
    </collision>
  </link>
  <link name="estop_link">
    <inertial>
      <origin xyz="0. 0. 0." rpy="0. 0. 0."/>
      <mass value="0.0019613"/>
      <inertia ixx="0." ixy="0." ixz="0." iyy="0." iyz="0." izz="0."/>
    </inertial>
    <visual>
      <origin xyz="0. 0. 0." rpy="0. -1.5707963 0. "/>
      <geometry>
        <mesh filename="meshes/estop_link_collisions.obj" scale="1. 1. 1."/>
      </geometry>
    </visual>
    <collision>
      <origin xyz="0. 0. 0." rpy="0. -1.5707963 0. "/>
      <geometry>
        <mesh filename="meshes/estop_link_collisions.obj" scale="1. 1. 1."/>
      </geometry>
    </collision>
  </link>
  <link name="fetch">
    <visual>
      <origin xyz="0. 0. 0." rpy="0. 0. 0."/>
      <geometry>
        <mesh filename="meshes/base_link_visuals.obj" scale="1. 1. 1."/>
      </geometry>
    </visual>
    <visual>
      <origin xyz="0. 0. 0." rpy="0. 0. 0."/>
      <geometry>
        <mesh filename="meshes/base_link_collisions.obj" scale="1. 1. 1."/>
      </geometry>
    </visual>
    <collision>
      <origin xyz="0. 0. 0." rpy="0. 0. 0."/>
      <geometry>
        <mesh filename="meshes/base_link_visuals.obj" scale="1. 1. 1."/>
      </geometry>
    </collision>
    <collision>
      <origin xyz="0. 0. 0." rpy="0. 0. 0."/>
      <geometry>
        <mesh filename="meshes/base_link_collisions.obj" scale="1. 1. 1."/>
      </geometry>
    </collision>
  </link>
  <link name="forearm_roll_link">
    <inertial>
      <origin xyz="0. 0. 0." rpy="0. 0. 0."/>
      <mass value="1.6562999"/>
      <inertia ixx="0." ixy="0." ixz="0." iyy="0." iyz="0." izz="0."/>
    </inertial>
    <visual>
      <origin xyz="0. 0. 0." rpy="0. 0. 0."/>
      <geometry>
        <mesh filename="meshes/forearm_roll_link_visuals.obj" scale="1. 1. 1."/>
      </geometry>
    </visual>
    <visual>
      <origin xyz="0. 0. 0." rpy="0. 0. 0."/>
      <geometry>
        <mesh filename="meshes/forearm_roll_link_collisions.obj" scale="1. 1. 1."/>
      </geometry>
    </visual>
    <collision>
      <origin xyz="0. 0. 0." rpy="0. 0. 0."/>
      <geometry>
        <mesh filename="meshes/forearm_roll_link_collisions.obj" scale="1. 1. 1."/>
      </geometry>
    </collision>
  </link>
  <link name="gripper_link">
    <inertial>
      <origin xyz="0. 0. 0." rpy="0. 0. 0."/>
      <mass value="1.5175"/>
      <inertia ixx="0." ixy="0." ixz="0." iyy="0." iyz="0." izz="0."/>
    </inertial>
    <visual>
      <origin xyz="0. 0. 0." rpy="0. 0. -1.5707964"/>
      <geometry>
        <mesh filename="meshes/gripper_link_visuals.obj" scale="1. 1. 1."/>
      </geometry>
    </visual>
    <visual>
      <origin xyz="0. 0. 0." rpy="0. 0. -1.5707964"/>
      <geometry>
        <mesh filename="meshes/gripper_link_collisions.obj" scale="1. 1. 1."/>
      </geometry>
    </visual>
    <collision>
      <origin xyz="0. 0. 0." rpy="0. 0. -1.5707964"/>
      <geometry>
        <mesh filename="meshes/gripper_link_collisions.obj" scale="1. 1. 1."/>
      </geometry>
    </collision>
  </link>
  <link name="head_camera_depth_frame"/>
  <link name="head_camera_depth_optical_frame"/>
  <link name="head_camera_link">
    <visual>
      <origin xyz="0.0012938 0. 0.0000523" rpy="1.5707964 0. 1.5707964"/>
      <geometry>
        <mesh filename="meshes/Case_front.obj" scale="1. 1. 1."/>
      </geometry>
    </visual>
    <visual>
      <origin xyz="0.0012938 0. 0.0000523" rpy="1.5707964 0. 1.5707964"/>
      <geometry>
        <mesh filename="meshes/Glass.obj" scale="1. 1. 1."/>
      </geometry>
    </visual>
    <visual>
      <origin xyz="0.0012938 0. 0.0000523" rpy="1.5707964 0. 1.5707964"/>
      <geometry>
        <mesh filename="meshes/Case_back.obj" scale="1. 1. 1."/>
      </geometry>
    </visual>
    <visual>
      <origin xyz="-0.0200062 -0.03701 -0.0089477" rpy="3.1415927 0. 1.5707964"/>
      <geometry>
        <mesh filename="meshes/USB_C.obj" scale="1. 1. 1."/>
      </geometry>
    </visual>
    <visual>
      <origin xyz="0.0012938 0. 0.0000523" rpy="1.5707964 0. 1.5707964"/>
      <geometry>
        <mesh filename="meshes/Mount.obj" scale="1. 1. 1."/>
      </geometry>
    </visual>
    <visual>
      <origin xyz="-0.0106262 0.0113 0.0000523" rpy="1.5707964 0. -1.5707964"/>
      <geometry>
        <mesh filename="meshes/Camera_module.obj" scale="1. 1. 1."/>
      </geometry>
    </visual>
    <visual>
      <origin xyz="0.0012938 0. 0.0000523" rpy="1.5707964 0. 1.5707964"/>
      <geometry>
        <mesh filename="meshes/Front_mask.obj" scale="1. 1. 1."/>
      </geometry>
    </visual>
    <visual>
      <origin xyz="0.0012938 0. 0.0000523" rpy="1.5707964 0. 1.5707964"/>
      <geometry>
        <mesh filename="meshes/camera_mask.obj" scale="1. 1. 1."/>
      </geometry>
    </visual>
  </link>
  <link name="head_camera_rgb_frame"/>
  <link name="head_camera_rgb_optical_frame"/>
  <link name="head_pan_link">
    <inertial>
      <origin xyz="0. 0. 0." rpy="0. 0. 0."/>
      <mass value="2.2556"/>
      <inertia ixx="0." ixy="0." ixz="0." iyy="0." iyz="0." izz="0."/>
    </inertial>
    <visual>
      <origin xyz="0. 0. 0." rpy="0. 1.5707963 0. "/>
      <geometry>
        <mesh filename="meshes/head_pan_link_visuals.obj" scale="1. 1. 1."/>
      </geometry>
    </visual>
    <visual>
      <origin xyz="0. 0. 0." rpy="0. 1.5707963 0. "/>
      <geometry>
        <mesh filename="meshes/head_pan_link_collisions.obj" scale="1. 1. 1."/>
      </geometry>
    </visual>
    <collision>
      <origin xyz="0. 0. 0." rpy="0. 1.5707963 0. "/>
      <geometry>
        <mesh filename="meshes/head_pan_link_collisions.obj" scale="1. 1. 1."/>
      </geometry>
    </collision>
  </link>
  <link name="head_tilt_link">
    <inertial>
      <origin xyz="0. 0. 0." rpy="0. 0. 0."/>
      <mass value="0.9087"/>
      <inertia ixx="0." ixy="0." ixz="0." iyy="0." iyz="0." izz="0."/>
    </inertial>
    <visual>
      <origin xyz="0. 0. 0." rpy="0. 0. -1.5707964"/>
      <geometry>
        <mesh filename="meshes/head_tilt_link_visuals.obj" scale="1. 1. 1."/>
      </geometry>
    </visual>
    <visual>
      <origin xyz="0. 0. 0." rpy="0. 0. -1.5707964"/>
      <geometry>
        <mesh filename="meshes/head_tilt_link_collisions.obj" scale="1. 1. 1."/>
      </geometry>
    </visual>
    <collision>
      <origin xyz="0. 0. 0." rpy="0. 0. -1.5707964"/>
      <geometry>
        <mesh filename="meshes/head_tilt_link_collisions.obj" scale="1. 1. 1."/>
      </geometry>
    </collision>
  </link>
  <link name="l_gripper_finger_link">
    <inertial>
      <origin xyz="0. 0. 0." rpy="0. 0. 0."/>
      <mass value="0.0798"/>
      <inertia ixx="0." ixy="0." ixz="0." iyy="0." iyz="0." izz="0."/>
    </inertial>
    <visual>
      <origin xyz="0.101425 0. 0. " rpy="0. 0. 1.5707964"/>
      <geometry>
        <mesh filename="meshes/l_gripper_finger_link_visuals.obj" scale="1. 1. 1."/>
      </geometry>
    </visual>
    <visual>
      <origin xyz="0.101425 0. 0. " rpy="0. 0. 1.5707964"/>
      <geometry>
        <mesh filename="meshes/l_gripper_finger_link_collisions.obj" scale="1. 1. 1."/>
      </geometry>
    </visual>
    <collision>
      <origin xyz="0.101425 0. 0. " rpy="0. 0. 1.5707964"/>
      <geometry>
        <mesh filename="meshes/l_gripper_finger_link_collisions.obj" scale="1. 1. 1."/>
      </geometry>
    </collision>
  </link>
  <link name="l_wheel_link">
    <inertial>
      <origin xyz="0. 0. 0." rpy="0. 0. 0."/>
      <mass value="4.3541999"/>
      <inertia ixx="0." ixy="0." ixz="0." iyy="0." iyz="0." izz="0."/>
    </inertial>
    <visual>
      <origin xyz="0. 0. 0." rpy="0. 0. -1.5707964"/>
      <geometry>
        <mesh filename="meshes/l_wheel_link_visuals.obj" scale="1. 1. 1."/>
      </geometry>
    </visual>
    <visual>
      <origin xyz="0. 0. 0." rpy="0. 0. -1.5707964"/>
      <geometry>
        <mesh filename="meshes/l_wheel_link_collisions.obj" scale="1. 1. 1."/>
      </geometry>
    </visual>
    <collision>
      <origin xyz="0. 0. 0." rpy="0. 0. -1.5707964"/>
      <geometry>
        <mesh filename="meshes/l_wheel_link_collisions.obj" scale="1. 1. 1."/>
      </geometry>
    </collision>
  </link>
  <link name="laser_link">
    <inertial>
      <origin xyz="0. 0. 0." rpy="0. 0. 0."/>
      <mass value="0.0083363"/>
      <inertia ixx="0." ixy="0." ixz="0." iyy="0." iyz="0." izz="0."/>
    </inertial>
    <visual>
      <origin xyz="0. 0. 0." rpy="0. -1.5707963 0. "/>
      <geometry>
        <mesh filename="meshes/laser_link_visuals.obj" scale="1. 1. 1."/>
      </geometry>
    </visual>
    <visual>
      <origin xyz="0. 0. 0." rpy="0. -1.5707963 0. "/>
      <geometry>
        <mesh filename="meshes/laser_link_collisions.obj" scale="1. 1. 1."/>
      </geometry>
    </visual>
    <collision>
      <origin xyz="0. 0. 0." rpy="0. -1.5707963 0. "/>
      <geometry>
        <mesh filename="meshes/laser_link_collisions.obj" scale="1. 1. 1."/>
      </geometry>
    </collision>
  </link>
  <link name="r_gripper_finger_link">
    <inertial>
      <origin xyz="0. 0. 0." rpy="0. 0. 0."/>
      <mass value="0.0798"/>
      <inertia ixx="0." ixy="0." ixz="0." iyy="0." iyz="0." izz="0."/>
    </inertial>
    <visual>
      <origin xyz="0.101425 0. 0. " rpy="0. 0. -1.5707964"/>
      <geometry>
        <mesh filename="meshes/r_gripper_finger_link_visuals.obj" scale="1. 1. 1."/>
      </geometry>
    </visual>
    <visual>
      <origin xyz="0.101425 0. 0. " rpy="0. 0. -1.5707964"/>
      <geometry>
        <mesh filename="meshes/r_gripper_finger_link_collisions.obj" scale="1. 1. 1."/>
      </geometry>
    </visual>
    <collision>
      <origin xyz="0.101425 0. 0. " rpy="0. 0. -1.5707964"/>
      <geometry>
        <mesh filename="meshes/r_gripper_finger_link_collisions.obj" scale="1. 1. 1."/>
      </geometry>
    </collision>
  </link>
  <link name="r_wheel_link">
    <inertial>
      <origin xyz="0. 0. 0." rpy="0. 0. 0."/>
      <mass value="4.3541999"/>
      <inertia ixx="0." ixy="0." ixz="0." iyy="0." iyz="0." izz="0."/>
    </inertial>
    <visual>
      <origin xyz="0. 0. 0." rpy="0. 0. -1.5707964"/>
      <geometry>
        <mesh filename="meshes/r_wheel_link_visuals.obj" scale="1. 1. 1."/>
      </geometry>
    </visual>
    <visual>
      <origin xyz="0. 0. 0." rpy="0. 0. -1.5707964"/>
      <geometry>
        <mesh filename="meshes/r_wheel_link_collisions.obj" scale="1. 1. 1."/>
      </geometry>
    </visual>
    <collision>
      <origin xyz="0. 0. 0." rpy="0. 0. -1.5707964"/>
      <geometry>
        <mesh filename="meshes/r_wheel_link_collisions.obj" scale="1. 1. 1."/>
      </geometry>
    </collision>
  </link>
  <link name="shoulder_lift_link">
    <inertial>
      <origin xyz="0. 0. 0." rpy="0. 0. 0."/>
      <mass value="2.6615"/>
      <inertia ixx="0." ixy="0." ixz="0." iyy="0." iyz="0." izz="0."/>
    </inertial>
    <visual>
      <origin xyz="0. 0. 0." rpy="0. 0. -1.5707964"/>
      <geometry>
        <mesh filename="meshes/shoulder_lift_link_visuals.obj" scale="1. 1. 1."/>
      </geometry>
    </visual>
    <visual>
      <origin xyz="0. 0. 0." rpy="0. 0. -1.5707964"/>
      <geometry>
        <mesh filename="meshes/shoulder_lift_link_collisions.obj" scale="1. 1. 1."/>
      </geometry>
    </visual>
    <collision>
      <origin xyz="0. 0. 0." rpy="0. 0. -1.5707964"/>
      <geometry>
        <mesh filename="meshes/shoulder_lift_link_collisions.obj" scale="1. 1. 1."/>
      </geometry>
    </collision>
  </link>
  <link name="shoulder_pan_link">
    <inertial>
      <origin xyz="0. 0. 0." rpy="0. 0. 0."/>
      <mass value="2.5587001"/>
      <inertia ixx="0." ixy="0." ixz="0." iyy="0." iyz="0." izz="0."/>
    </inertial>
    <visual>
      <origin xyz="0. 0. 0." rpy="0. 1.5707963 0. "/>
      <geometry>
        <mesh filename="meshes/shoulder_pan_link_visuals.obj" scale="1. 1. 1."/>
      </geometry>
    </visual>
    <visual>
      <origin xyz="0. 0. 0." rpy="0. 1.5707963 0. "/>
      <geometry>
        <mesh filename="meshes/shoulder_pan_link_collisions.obj" scale="1. 1. 1."/>
      </geometry>
    </visual>
    <collision>
      <origin xyz="0. 0. 0." rpy="0. 1.5707963 0. "/>
      <geometry>
        <mesh filename="meshes/shoulder_pan_link_collisions.obj" scale="1. 1. 1."/>
      </geometry>
    </collision>
  </link>
  <link name="torso_fixed_link">
    <inertial>
      <origin xyz="0. 0. 0." rpy="0. 0. 0."/>
      <mass value="13.2775002"/>
      <inertia ixx="0." ixy="0." ixz="0." iyy="0." iyz="0." izz="0."/>
    </inertial>
    <visual>
      <origin xyz="0. 0. 0." rpy="0. 0. -1.5707964"/>
      <geometry>
        <mesh filename="meshes/torso_fixed_link_visuals.obj" scale="1. 1. 1."/>
      </geometry>
    </visual>
    <visual>
      <origin xyz="0. 0. 0." rpy="0. 0. -1.5707964"/>
      <geometry>
        <mesh filename="meshes/torso_fixed_link_collisions.obj" scale="1. 1. 1."/>
      </geometry>
    </visual>
    <collision>
      <origin xyz="0. 0. 0." rpy="0. 0. -1.5707964"/>
      <geometry>
        <mesh filename="meshes/torso_fixed_link_collisions.obj" scale="1. 1. 1."/>
      </geometry>
    </collision>
  </link>
  <link name="torso_lift_link">
    <inertial>
      <origin xyz="0. 0. 0." rpy="0. 0. 0."/>
      <mass value="10.7796001"/>
      <inertia ixx="0." ixy="0." ixz="0." iyy="0." iyz="0." izz="0."/>
    </inertial>
    <visual>
      <origin xyz="0. 0. 0." rpy="0. 1.5707963 0. "/>
      <geometry>
        <mesh filename="meshes/torso_lift_link_visuals.obj" scale="1. 1. 1."/>
      </geometry>
    </visual>
    <visual>
      <origin xyz="0. 0. 0." rpy="0. 1.5707963 0. "/>
      <geometry>
        <mesh filename="meshes/torso_lift_link_collisions.obj" scale="1. 1. 1."/>
      </geometry>
    </visual>
    <collision>
      <origin xyz="0. 0. 0." rpy="0. 1.5707963 0. "/>
      <geometry>
        <mesh filename="meshes/torso_lift_link_collisions.obj" scale="1. 1. 1."/>
      </geometry>
    </collision>
  </link>
  <link name="upperarm_roll_link">
    <inertial>
      <origin xyz="0. 0. 0." rpy="0. 0. 0."/>
      <mass value="2.3311"/>
      <inertia ixx="0." ixy="0." ixz="0." iyy="0." iyz="0." izz="0."/>
    </inertial>
    <visual>
      <origin xyz="0. 0. 0." rpy="0. 0. 0."/>
      <geometry>
        <mesh filename="meshes/upperarm_roll_link_visuals.obj" scale="1. 1. 1."/>
      </geometry>
    </visual>
    <visual>
      <origin xyz="0. 0. 0." rpy="0. 0. 0."/>
      <geometry>
        <mesh filename="meshes/upperarm_roll_link_collisions.obj" scale="1. 1. 1."/>
      </geometry>
    </visual>
    <collision>
      <origin xyz="0. 0. 0." rpy="0. 0. 0."/>
      <geometry>
        <mesh filename="meshes/upperarm_roll_link_collisions.obj" scale="1. 1. 1."/>
      </geometry>
    </collision>
  </link>
  <link name="wrist_flex_link">
    <inertial>
      <origin xyz="0. 0. 0." rpy="0. 0. 0."/>
      <mass value="1.725"/>
      <inertia ixx="0." ixy="0." ixz="0." iyy="0." iyz="0." izz="0."/>
    </inertial>
    <visual>
      <origin xyz="0. 0. 0." rpy="0. 0. -1.5707964"/>
      <geometry>
        <mesh filename="meshes/wrist_flex_link_visuals.obj" scale="1. 1. 1."/>
      </geometry>
    </visual>
    <visual>
      <origin xyz="0. 0. 0." rpy="0. 0. -1.5707964"/>
      <geometry>
        <mesh filename="meshes/wrist_flex_link_collisions.obj" scale="1. 1. 1."/>
      </geometry>
    </visual>
    <collision>
      <origin xyz="0. 0. 0." rpy="0. 0. -1.5707964"/>
      <geometry>
        <mesh filename="meshes/wrist_flex_link_collisions.obj" scale="1. 1. 1."/>
      </geometry>
    </collision>
  </link>
  <link name="wrist_roll_link">
    <inertial>
      <origin xyz="0. 0. 0." rpy="0. 0. 0."/>
      <mass value="0.1354"/>
      <inertia ixx="0." ixy="0." ixz="0." iyy="0." iyz="0." izz="0."/>
    </inertial>
    <visual>
      <origin xyz="0. 0. 0." rpy="0. 0. 0."/>
      <geometry>
        <mesh filename="meshes/wrist_roll_link_visuals.obj" scale="1. 1. 1."/>
      </geometry>
    </visual>
    <visual>
      <origin xyz="0. 0. 0." rpy="0. 0. 0."/>
      <geometry>
        <mesh filename="meshes/wrist_roll_link_collisions.obj" scale="1. 1. 1."/>
      </geometry>
    </visual>
    <collision>
      <origin xyz="0. 0. 0." rpy="0. 0. 0."/>
      <geometry>
        <mesh filename="meshes/wrist_roll_link_collisions.obj" scale="1. 1. 1."/>
      </geometry>
    </collision>
  </link>
</robot>
